Database URL: ep-shrill-breeze-a5pq5psv.us-east-2.aws.neon.tech
Traceback (most recent call last):
  File "/home/runner/BenefitHub/.pythonlibs/lib/python3.11/site-packages/sqlalchemy/engine/base.py", line 2118, in _exec_insertmany_context
    dialect.do_execute(
  File "/home/runner/BenefitHub/.pythonlibs/lib/python3.11/site-packages/sqlalchemy/engine/default.py", line 941, in do_execute
    cursor.execute(statement, parameters)
psycopg2.errors.UniqueViolation: duplicate key value violates unique constraint "ix_category_name"
DETAIL:  Key (name)=(Educación) already exists.


The above exception was the direct cause of the following exception:

Traceback (most recent call last):
  File "/home/runner/BenefitHub/main.py", line 18, in <module>
    seed_data()  # Seed the database with initial data
    ^^^^^^^^^^^
  File "/home/runner/BenefitHub/app/seed_data.py", line 19, in seed_data
    db.session.commit()
  File "/home/runner/BenefitHub/.pythonlibs/lib/python3.11/site-packages/sqlalchemy/orm/scoping.py", line 597, in commit
    return self._proxied.commit()
           ^^^^^^^^^^^^^^^^^^^^^^
  File "/home/runner/BenefitHub/.pythonlibs/lib/python3.11/site-packages/sqlalchemy/orm/session.py", line 2028, in commit
    trans.commit(_to_root=True)
  File "<string>", line 2, in commit
  File "/home/runner/BenefitHub/.pythonlibs/lib/python3.11/site-packages/sqlalchemy/orm/state_changes.py", line 139, in _go
    ret_value = fn(self, *arg, **kw)
                ^^^^^^^^^^^^^^^^^^^^
  File "/home/runner/BenefitHub/.pythonlibs/lib/python3.11/site-packages/sqlalchemy/orm/session.py", line 1313, in commit
    self._prepare_impl()
  File "<string>", line 2, in _prepare_impl
  File "/home/runner/BenefitHub/.pythonlibs/lib/python3.11/site-packages/sqlalchemy/orm/state_changes.py", line 139, in _go
    ret_value = fn(self, *arg, **kw)
                ^^^^^^^^^^^^^^^^^^^^
  File "/home/runner/BenefitHub/.pythonlibs/lib/python3.11/site-packages/sqlalchemy/orm/session.py", line 1288, in _prepare_impl
    self.session.flush()
  File "/home/runner/BenefitHub/.pythonlibs/lib/python3.11/site-packages/sqlalchemy/orm/session.py", line 4352, in flush
    self._flush(objects)
  File "/home/runner/BenefitHub/.pythonlibs/lib/python3.11/site-packages/sqlalchemy/orm/session.py", line 4487, in _flush
    with util.safe_reraise():
  File "/home/runner/BenefitHub/.pythonlibs/lib/python3.11/site-packages/sqlalchemy/util/langhelpers.py", line 146, in __exit__
    raise exc_value.with_traceback(exc_tb)
  File "/home/runner/BenefitHub/.pythonlibs/lib/python3.11/site-packages/sqlalchemy/orm/session.py", line 4448, in _flush
    flush_context.execute()
  File "/home/runner/BenefitHub/.pythonlibs/lib/python3.11/site-packages/sqlalchemy/orm/unitofwork.py", line 466, in execute
    rec.execute(self)
  File "/home/runner/BenefitHub/.pythonlibs/lib/python3.11/site-packages/sqlalchemy/orm/unitofwork.py", line 642, in execute
    util.preloaded.orm_persistence.save_obj(
  File "/home/runner/BenefitHub/.pythonlibs/lib/python3.11/site-packages/sqlalchemy/orm/persistence.py", line 93, in save_obj
    _emit_insert_statements(
  File "/home/runner/BenefitHub/.pythonlibs/lib/python3.11/site-packages/sqlalchemy/orm/persistence.py", line 1143, in _emit_insert_statements
    result = connection.execute(
             ^^^^^^^^^^^^^^^^^^^
  File "/home/runner/BenefitHub/.pythonlibs/lib/python3.11/site-packages/sqlalchemy/engine/base.py", line 1418, in execute
    return meth(
           ^^^^^
  File "/home/runner/BenefitHub/.pythonlibs/lib/python3.11/site-packages/sqlalchemy/sql/elements.py", line 515, in _execute_on_connection
    return connection._execute_clauseelement(
           ^^^^^^^^^^^^^^^^^^^^^^^^^^^^^^^^^^
  File "/home/runner/BenefitHub/.pythonlibs/lib/python3.11/site-packages/sqlalchemy/engine/base.py", line 1640, in _execute_clauseelement
    ret = self._execute_context(
          ^^^^^^^^^^^^^^^^^^^^^^
  File "/home/runner/BenefitHub/.pythonlibs/lib/python3.11/site-packages/sqlalchemy/engine/base.py", line 1844, in _execute_context
    return self._exec_insertmany_context(dialect, context)
           ^^^^^^^^^^^^^^^^^^^^^^^^^^^^^^^^^^^^^^^^^^^^^^^
  File "/home/runner/BenefitHub/.pythonlibs/lib/python3.11/site-packages/sqlalchemy/engine/base.py", line 2126, in _exec_insertmany_context
    self._handle_dbapi_exception(
  File "/home/runner/BenefitHub/.pythonlibs/lib/python3.11/site-packages/sqlalchemy/engine/base.py", line 2355, in _handle_dbapi_exception
    raise sqlalchemy_exception.with_traceback(exc_info[2]) from e
  File "/home/runner/BenefitHub/.pythonlibs/lib/python3.11/site-packages/sqlalchemy/engine/base.py", line 2118, in _exec_insertmany_context
    dialect.do_execute(
  File "/home/runner/BenefitHub/.pythonlibs/lib/python3.11/site-packages/sqlalchemy/engine/default.py", line 941, in do_execute
    cursor.execute(statement, parameters)
sqlalchemy.exc.IntegrityError: (psycopg2.errors.UniqueViolation) duplicate key value violates unique constraint "ix_category_name"
DETAIL:  Key (name)=(Educación) already exists.

[SQL: INSERT INTO category (name, image_url) SELECT p0::VARCHAR, p1::VARCHAR FROM (VALUES (%(name__0)s, %(image_url__0)s, 0), (%(name__1)s, %(image_url__1)s, 1), (%(name__2)s, %(image_url__2)s, 2), (%(name__3)s, %(image_url__3)s, 3), (%(name__4)s, %(image_url__4)s, 4), (%(name__5)s, %(image_url__5)s, 5), (%(name__6)s, %(image_url__6)s, 6), (%(name__7)s, %(image_url__7)s, 7)) AS imp_sen(p0, p1, sen_counter) ORDER BY sen_counter RETURNING category.id, category.id AS id__1]
[parameters: {'image_url__0': 'https://placehold.co/400x300?text=Educacion', 'name__0': 'Educación', 'image_url__1': 'https://placehold.co/400x300?text=Belleza', 'name__1': 'Belleza', 'image_url__2': 'https://placehold.co/400x300?text=Comida', 'name__2': 'Comida', 'image_url__3': 'https://placehold.co/400x300?text=Deportes', 'name__3': 'Deportes', 'image_url__4': 'https://placehold.co/400x300?text=Salud', 'name__4': 'Salud', 'image_url__5': 'https://placehold.co/400x300?text=Entretenimiento', 'name__5': 'Entretenimiento', 'image_url__6': 'https://placehold.co/400x300?text=Viajes', 'name__6': 'Viajes', 'image_url__7': 'https://placehold.co/400x300?text=Mascotas', 'name__7': 'Mascotas'}]
(Background on this error at: https://sqlalche.me/e/20/gkpj)